Workbook

Sheet How to Use
B1: How to Use This TRIZ Navigator
B3: TRIZ Navigator tab | C3: Start here every time you have a new problem. Work top to bottom through the 7 steps.
B5: Step 1 — Problem | C5: Name the system and describe the problem concisely. Write the Ideal Final Result (IFR) — what would the system do if it solved itself?
B7: Step 2 — Contradiction map | C7: Fill the three cells: what gets better, the bad partial solution, what gets worse. Then choose Technical or Physical contradiction from the dropdown.
B9: Step 3A — Technical contradiction | C9: Name the improving and worsening engineering parameters. Then check the TC Matrix tab for principle recommendations, or enter your own principle numbers in Step 4.
B11: Step 3B — Physical contradiction | C11: State the parameter and its two required opposite states. Choose a separation strategy from the dropdown. Then see the Separation Principles tab for the principle list.
B13: Step 4 — Principles | C13: Enter principle numbers in column B. Column C auto-looks up the name; column E auto-looks up the definition from the Appendix. Add your own 'why it applies' note in column D.
B15: Step 5 — Solutions map | C15: Fill the 9-box grid thinking across Past/Present/Future and Sub-system/System/Super-system. Each cell holds one idea or observation — no need to fill all 9.
B17: Step 6 — Innovation level | C17: 22. Loss of energy | E17: =IFERROR(VLOOKUP(B17&"||"&C17, LookupData!$C:$D, 2, FALSE), "Manual lookup needed")
C19: Document next actions, owner, date, and status. Use the Status dropdown to track progress.
B21: TC Matrix tab | C21: Quick reference for 15 common parameter conflict pairs and their recommended principles. Use as a starting point, not an exhaustive lookup.
B23: Separation Principles tab | C23: Full list of inventive principles grouped under each of the 4 separation strategies. Select the strategy matching your Step 3B dropdown choice.
B25: Appendix tab | C25: All 40 TRIZ inventive principles with full definition, an engineering example, and an everyday cross-industry example. Auto-linked from Step 4 via VLOOKUP.
B27: Repeating the tool | C27: To start a new problem: copy the TRIZ Navigator sheet (right-click tab → Move or Copy → tick 'Create a copy'). The copy starts blank and fully functional.
B30: New in v2 — four enhancements added
B32: Altshuller Matrix | C32: The full 39×39 matrix. Row = parameter to improve (green); Column = parameter that worsens (red). Teal cell = principle numbers recommended. Grey = no standard mapping, use physical contradiction path. Freeze pane lets you scroll while keeping headers visible.
B34: Principle Scoring | C34: Enter shortlisted principle numbers in column B — names auto-fill. Score Feasibility, Impact, Speed, and Cost (1–5 each). Priority Score is auto-weighted (max 20). Best-scoring principle shown at the bottom. Add rationale notes in column I.
B36: Case Study Library | C36: 12 real-world TRIZ examples across semiconductor, aerospace, automotive, medical devices, software, and more. Study the contradiction type and principles used, then draw analogies to your own problem.
B38: Problem History Log | C38: Log every TRIZ session: system, problem, contradiction path, principles, innovation level, solution, and status. Row 4 is pre-filled with the HBM stack session as an example. Session statistics at the bottom auto-update as you add rows.

Sheet TRIZ Navigator
B2: TRIZ Creative Problem Solving Navigator
B4: STEP 1 — Define Your Problem
B5: System / Product name
B6: Problem description
B7: Ideal Final Result (IFR)
B9: STEP 2 — Map Your Contradiction
B10: What gets BETTER | C10: Bad solution / tradeoff | D10: What gets WORSE | E10: Contradiction type
E11: Technical Contradiction
B15: STEP 3A — Technical Contradiction (use when two parameters conflict)
B16: Parameter to IMPROVE | C16: Parameter that WORSENS | D16: Engineering domain / context | E16: → Suggested Principles
B17: 1. Weight of moving object | C17: 28. Measurement accuracy | E17: =IFERROR(VLOOKUP(B17&"||"&C17, LookupData!$C:$D, 2, FALSE), "Manual lookup needed")
A19: Principle Slot 1: | B19: DETAILED PRINCIPLE BREAKDOWN (Auto-populated): | C19: =IF(TRIM(MID(SUBSTITUTE(SUBSTITUTE(TRIM($E$17),","," ")," ",REPT(" ",100)),(1-1)*100+1,100))<>"", IFERROR(VLOOKUP(VALUE(TRIM(MID(SUBSTITUTE(SUBSTITUTE(TRIM($E$17),","," ")," ",REPT(" ",100)),(1-1)*100+1,100))), DetailedPrinciples!A:C, 3, FALSE), ""), "")
A20: Principle Slot 2: | B20: =IF(TRIM(MID(SUBSTITUTE(SUBSTITUTE(TRIM($E$17),","," ")," ",REPT(" ",100)),(1-1)*100+1,100))<>"", "P" & TRIM(MID(SUBSTITUTE(SUBSTITUTE(TRIM($E$17),","," ")," ",REPT(" ",100)),(1-1)*100+1,100)) & ": " & IFERROR(VLOOKUP(VALUE(TRIM(MID(SUBSTITUTE(SUBSTITUTE(TRIM($E$17),","," ")," ",REPT(" ",100)),(1-1)*100+1,100))), DetailedPrinciples!A:C, 2, FALSE), ""), "") | C20: =IF(TRIM(MID(SUBSTITUTE(SUBSTITUTE(TRIM($E$17),","," ")," ",REPT(" ",100)),(1-1)*100+1,100))<>"", IFERROR(VLOOKUP(VALUE(TRIM(MID(SUBSTITUTE(SUBSTITUTE(TRIM($E$17),","," ")," ",REPT(" ",100)),(1-1)*100+1,100))), DetailedPrinciples!A:C, 3, FALSE), ""), "")
A21: Principle Slot 3: | B21: =IF(TRIM(MID(SUBSTITUTE(SUBSTITUTE(TRIM($E$17),","," ")," ",REPT(" ",100)),(2-1)*100+1,100))<>"", "P" & TRIM(MID(SUBSTITUTE(SUBSTITUTE(TRIM($E$17),","," ")," ",REPT(" ",100)),(2-1)*100+1,100)) & ": " & IFERROR(VLOOKUP(VALUE(TRIM(MID(SUBSTITUTE(SUBSTITUTE(TRIM($E$17),","," ")," ",REPT(" ",100)),(2-1)*100+1,100))), DetailedPrinciples!A:C, 2, FALSE), ""), "") | C21: =IF(TRIM(MID(SUBSTITUTE(SUBSTITUTE(TRIM($E$17),","," ")," ",REPT(" ",100)),(2-1)*100+1,100))<>"", IFERROR(VLOOKUP(VALUE(TRIM(MID(SUBSTITUTE(SUBSTITUTE(TRIM($E$17),","," ")," ",REPT(" ",100)),(2-1)*100+1,100))), DetailedPrinciples!A:C, 3, FALSE), ""), "")
A22: Principle Slot 4: | B22: =IF(TRIM(MID(SUBSTITUTE(SUBSTITUTE(TRIM($E$17),","," ")," ",REPT(" ",100)),(3-1)*100+1,100))<>"", "P" & TRIM(MID(SUBSTITUTE(SUBSTITUTE(TRIM($E$17),","," ")," ",REPT(" ",100)),(3-1)*100+1,100)) & ": " & IFERROR(VLOOKUP(VALUE(TRIM(MID(SUBSTITUTE(SUBSTITUTE(TRIM($E$17),","," ")," ",REPT(" ",100)),(3-1)*100+1,100))), DetailedPrinciples!A:C, 2, FALSE), ""), "") | C22: =IF(TRIM(MID(SUBSTITUTE(SUBSTITUTE(TRIM($E$17),","," ")," ",REPT(" ",100)),(3-1)*100+1,100))<>"", IFERROR(VLOOKUP(VALUE(TRIM(MID(SUBSTITUTE(SUBSTITUTE(TRIM($E$17),","," ")," ",REPT(" ",100)),(3-1)*100+1,100))), DetailedPrinciples!A:C, 3, FALSE), ""), "")
B23: =IF(TRIM(MID(SUBSTITUTE(SUBSTITUTE(TRIM($E$17),","," ")," ",REPT(" ",100)),(4-1)*100+1,100))<>"", "P" & TRIM(MID(SUBSTITUTE(SUBSTITUTE(TRIM($E$17),","," ")," ",REPT(" ",100)),(4-1)*100+1,100)) & ": " & IFERROR(VLOOKUP(VALUE(TRIM(MID(SUBSTITUTE(SUBSTITUTE(TRIM($E$17),","," ")," ",REPT(" ",100)),(4-1)*100+1,100))), DetailedPrinciples!A:C, 2, FALSE), ""), "") | C23: =IF(TRIM(MID(SUBSTITUTE(SUBSTITUTE(TRIM($E$17),","," ")," ",REPT(" ",100)),(4-1)*100+1,100))<>"", IFERROR(VLOOKUP(VALUE(TRIM(MID(SUBSTITUTE(SUBSTITUTE(TRIM($E$17),","," ")," ",REPT(" ",100)),(4-1)*100+1,100))), DetailedPrinciples!A:C, 3, FALSE), ""), "")
B26: STEP 3B — Physical Contradiction (use when one parameter must be opposite states)
B27: The parameter / property | C27: Must be (State A) | D27: AND also be (State B) | E27: Separation strategy
E28: Separate in Time
B34: STEP 4 — Distilled TRIZ Inventive Principles
B35: Principle # | C35: Principle name | D35: Why it applies to your problem | E35: See Appendix tab for full definition & examples
E36: =IFERROR(VLOOKUP(B31,Appendix!$A:$B,2,0),"")
E37: =IFERROR(VLOOKUP(B32,Appendix!$A:$B,2,0),"")
E38: =IFERROR(VLOOKUP(B33,Appendix!$A:$B,2,0),"")
E40: =IFERROR(VLOOKUP(B35,Appendix!$A:$B,2,0),"")
E42: =IFERROR(VLOOKUP(B37,Appendix!$A:$B,2,0),"")
E43: =IFERROR(VLOOKUP(B38,Appendix!$A:$B,2,0),"")
C47: PAST | D47: PRESENT | E47: FUTURE
B50: SYSTEM
B52: SUB-SYSTEM
B55: STEP 6 — Target Innovation Level
B56: Level 1 | C56: Apparent (32%) — simple improvements using company knowledge | E56: Level 2
B57: Level 2
B58: Level 3 | C58: Fundamental change (18%) — radical innovation from other fields
B59: Level 4 | C59: New application (<4%) — new combination of technologies
B60: Level 5 | C60: Breakthrough (<1%) — new invention based on new science
B62: STEP 7 — Next Actions & Owner
B63: Action item | C63: Owner | D63: Target date | E63: Status

Sheet Altshuller Matrix
B1: Altshuller Contradiction Matrix — Full 39×39 (Oxford Creativity reference)
B2: ROW = Parameter to IMPROVE (green) | COLUMN = Parameter that WORSENS (red) | Teal cell = recommended TRIZ principles | Grey = no standard recommendation (use physical contradiction path)
C3: 1. Weight of moving object | D3: 2. Weight of stationary object | E3: 3. Length of moving object | F3: 4. Length of stationary object | G3: 5. Area of moving object | H3: 6. Area of stationary object | I3: 7. Volume of moving object | J3: 8. Volume of stationary object | K3: 9. Speed | L3: 10. Force | M3: 11. Stress or pressure | N3: 12. Shape | O3: 13. Stability of object composition | P3: 14. Strength | Q3: 15. Duration of action - moving | R3: 16. Duration of action - stationary | S3: 17. Temperature | T3: 18. Illumination intensity | U3: 19. Use of energy by moving object | V3: 20. Use of energy by stationary object | W3: 21. Power | X3: 22. Loss of energy | Y3: 23. Loss of substance | Z3: 24. Loss of information | AA3: 25. Loss of time | AB3: 26. Amount of substance | AC3: 27. Reliability | AD3: 28. Measurement accuracy | AE3: 29. Manufacturing precision | AF3: 30. Object-generated harmful effects | AG3: 31. Harmful side effects | AH3: 32. Ease of manufacture | AI3: 33. Ease of operation | AJ3: 34. Ease of repair | AK3: 35. Adaptability or versatility | AL3: 36. Device complexity | AM3: 37. Difficulty of detecting and measuring | AN3: 38. Extent of automation | AO3: 39. Productivity
B4: 1. Weight of moving object | C4: — | D4: 15,8,29,34 | E4: 29,17,38,34 | G4: 29,2,40,28 | I4: 2,8,15,38 | K4: 2,28,13,38 | L4: 8,1,37,18 | M4: 17,10,4 | N4: 1,8,15,34 | O4: 28,10 | P4: 1,8,40,15 | Q4: 15,14,28,26 | S4: 35,10,3,21 | U4: 35,19,18,37 | W4: 12,18,28,31 | X4: 6,2,34,19 | Y4: 5,35,3,31 | AA4: 10,24,35,19 | AB4: 35,26 | AC4: 22,21,40,4 | AD4: 28,32,1,24 | AE4: 28,32,13,18 | AF4: 22,21,18,27 | AG4: 22,35,31,39 | AH4: 27,28,1,36 | AI4: 35,3,2,24 | AJ4: 29,3,8,25 | AK4: 1,28,35,6 | AL4: 26,27,13 | AM4: 28,26,18,35 | AN4: 22,21,18,27 | AO4: 35,26,24,37
B5: 2. Weight of stationary object | C5: 10,1,29,35 | D5: — | F5: 35,28,40,29 | H5: 17,28 | J5: 10,28,19,39 | L5: 8,10,19,35 | M5: 13,19,10,37 | N5: 17,9,15 | O5: 28,10 | P5: 10,28,8 | R5: 35,10,21 | V5: 19,18,36,40 | X5: 18,19,28,1 | Y5: 15,18,35,34 | AA5: 10,20,26,5 | AC5: 10,35,29,39 | AD5: 28,32,10 | AE5: 28,32,10 | AF5: 35,11,22,31 | AG5: 22,19,29,40 | AH5: 35,10,16 | AI5: 1,6 | AJ5: 13,1,26,24 | AK5: 15,29,28 | AL5: 26 | AM5: 30,10,14,1 | AN5: 30,10,14,1 | AO5: 1,10,34,28
B6: 3. Length of moving object | C6: 8,15,29,34 | E6: — | F6: 15,17,4 | G6: 7,17,4,35 | I6: 13,4,8 | K6: 13,28 | L6: 17,10,4 | M6: 1,8,35 | N6: 1,15,8,35 | O6: 28,10 | P6: 8,35,29,34 | Q6: 19 | S6: 10,15,19 | T6: 32 | U6: 19,10,32,18 | X6: 10,35,34,20 | Y6: 10,28,29,35 | Z6: 10,28,29,35 | AA6: 14,26,28,25 | AB6: 3,35,38,18 | AC6: 13,35 | AD6: 32,28,13 | AE6: 32,28,13 | AF6: 22,1,3,35 | AG6: 17,1,39,4 | AH6: 17,24,26,16 | AI6: 14,4,28,29 | AJ6: 1,4 | AK6: 17,15 | AL6: 1,17,13,12 | AM6: 1,17,13,16 | AO6: 14,4,28,29
B7: 4. Length of stationary object | D7: 35,28,40,29 | E7: 15,17,4 | F7: — | H7: 17,7,10,40 | J7: 35,8,2,14 | M7: 28,10 | N7: 1,14,35 | O7: 28,10 | P7: 3,35,38,18 | R7: 35,10,21 | T7: 2,26 | V7: 1,26 | Y7: 10,28,35,23 | AA7: 12,28,10,24 | AC7: 3,35,13 | AD7: 1,32 | AE7: 25,10 | AF7: 35,28,9,10 | AG7: 10,28,24,35 | AH7: 1,35,20,10 | AI7: 13,3,36,24 | AJ7: 15,37,8 | AK7: 15,10,37,28 | AL7: 26,1 | AM7: 29,1,4,16 | AN7: 2,18,37 | AO7: 28,10,29,35
B8: 5. Area of moving object | C8: 2,17,29,4 | E8: 14,15,18,4 | G8: — | H8: 30,2 | I8: 26,7,9,39 | K8: 2,38 | L8: 19,30,35,2 | M8: 15,17,30,26 | N8: 26,7,9,39 | O8: 2,11,13 | P8: 10,28,15 | Q8: 5,34,29,4 | S8: 2,15,16 | T8: 15,32 | U8: 15,30,14,28 | X8: 15,26,17,13 | Y8: 17,26,38,10 | Z8: 14,9,13,15 | AA8: 2,6,34,14 | AB8: 10,15,17,7 | AC8: 10,22,29,40 | AD8: 28,32,3 | AE8: 32,28,3,16 | AF8: 2,25,28,39 | AG8: 1,28,10 | AH8: 1,32,10,25 | AI8: 1,32,13,11 | AJ8: 2,28,10,25 | AK8: 15,17,30,26 | AL8: 2,26,35 | AM8: 32,26,28,18 | AN8: 2,25,16 | AO8: 12,28,35
B9: 6. Area of stationary object | D9: 17,28 | F9: 17,7,10,40 | G9: 30,2 | H9: — | J9: 10,40,28,2 | K9: 3,35 | L9: 10,15,36,28 | M9: 10,15,36,37 | N9: 2,38 | O9: 35,10,14 | U9: 16,17,26,24 | Y9: 16,17,26,24 | AA9: 16,4 | AB9: 16,4 | AC9: 10,35,4,18 | AD9: 28,32,3 | AE9: 3,35,38,18 | AF9: 22,21,3,35 | AG9: 27,2,39,35 | AH9: 10,35,28,24 | AI9: 35,1,13,11 | AJ9: 35,1,13,11 | AK9: 1,32 | AL9: 26,2 | AM9: 36,28,40,19 | AO9: 35,10,38,19
B10: 7. Volume of moving object | C10: 2,26,29,40 | E10: 1,7,4,35 | G10: 1,7,4,17 | I10: — | K10: 29,4,38,34 | L10: 15,35,36,37 | M10: 6,35,36,37 | N10: 1,15,29,4 | O10: 28,10,1 | P10: 9,14,15,7 | Q10: 6,35,4 | S10: 34,39,40,18 | T10: 2,13,10 | U10: 35,6,13,18 | V10: 7,2,35 | X10: 16,35,38 | Y10: 2,20,22 | Z10: 26,24 | AA10: 35,6,13,18 | AB10: 10,6,2,34 | AC10: 39,35,34,10 | AD10: 28,32,4 | AE10: 28,32,4,22 | AF10: 22,21,27,35 | AG10: 34,10,28 | AH10: 10,28,32 | AI10: 15,34,33 | AJ10: 35,10,28,23 | AK10: 10,28,29,4 | AL10: 7,15,13,16 | AM10: 35,15,18,34 | AN10: 35,10,38 | AO10: 10,28,29,35
B11: 8. Volume of stationary object | D11: 10,28,19,39 | F11: 35,8,2,14 | H11: 10,40,28,2 | J11: — | L11: 2,18,37 | M11: 24,35 | N11: 7,2,35 | O11: 34,28,35,40 | P11: 9,14,17,15 | R11: 35,10,21 | V11: 35,10,19,14 | Y11: 28,18,10,40 | AA11: 30,27 | AB11: 3,34,40,29 | AC11: 10,35,4 | AD11: 28,32,1 | AE11: 28,35,10,23 | AF11: 35,10,21 | AG11: 28,10,21,35 | AH11: 1,35,10,28 | AI11: 13,3,36,24 | AJ11: 15,37,8 | AK11: 15,10,37,28 | AL11: 26,1 | AM11: 29,1,4,16 | AN11: 2,18,37 | AO11: 28,10,29,35
B12: 9. Speed | C12: 2,28,13,38 | E12: 13,28,15 | G12: 29,30,34 | H12: 7,29,34 | I12: 13,28,15,19 | K12: — | L12: 28,33,1,18 | M12: 8,3,26,14 | N12: 15,37,19 | O12: 28,15 | P12: 18,13,34 | Q12: 10,37,36 | S12: 28,30,36,2 | U12: 13,28,15,12 | W12: 6,18,38,40 | X12: 35,15,18,34 | Y12: 35,10,21 | Z12: 10,20,37,35 | AA12: 35,4,34,10 | AB12: 16,35,10 | AC12: 28,33,18,4 | AD12: 10,37,4 | AE12: 14,10,34,40 | AF12: 35,2,10,3 | AG12: 10,40,16 | AH12: 28,32,1 | AI12: 32,28,2,24 | AJ12: 34,10,28 | AK12: 10,28,32,25 | AL12: 13,26 | AM12: 2,6,34,14 | AN12: 35,10,34,28 | AO12: 28,10,29,35
B13: 10. Force | C13: 8,1,37,18 | D13: 8,10,19,35 | E13: 17,10,4 | G13: 19,30,35,2 | H13: 1,18,36,37 | I13: 15,9,12,37 | J13: 2,36,25 | K13: 13,28,15,12 | L13: — | M13: 36,35,21 | N13: 35,10,37,40 | O13: 35,1,14,16 | P13: 10,35,40 | Q13: 19,2,35,32 | S13: 35,10,21 | T13: 1 | U13: 35,10,21 | W13: 19,17,10 | X13: 1,6 | Y13: 10,35,4 | Z13: 14,2 | AA13: 15,4,17,28 | AB13: 3,35,13,21 | AC13: 35,10,14,3 | AD13: 15,17,30,26 | AE13: 15,29,28 | AF13: 14,15,22,35 | AG13: 10,3,18,40 | AH13: 26,32,27 | AI13: 26,10,28 | AJ13: 10,26,35 | AK13: 19,35,10,38 | AL13: 16,26,21,2 | AM13: 36,37 | AN13: 14,10,34,40 | AO13: 35,28,2,24
B14: 11. Stress or pressure | C14: 10,36,37,40 | D14: 13,19,10,37 | E14: 1,8,35 | F14: 28,10 | G14: 19,10,15 | H14: 10,15,36,37 | I14: 35,22,40,15 | J14: 24,35 | K14: 28,15,10,36 | L14: 36,35,21 | M14: — | N14: 35,10,40,34 | O14: 35,4,15,10 | P14: 35,33,2,40 | Q14: 9,18,3,40 | S14: 35,39,19,2 | U14: 14,24,10,37 | W14: 10,35,14 | X14: 2,36,25 | Y14: 35,24 | Z14: 10,14,35 | AA14: 35,4,15,10 | AB14: 35,33,29,31 | AC14: 10,35,40,4 | AD14: 28,32,1 | AE14: 3,35,40,10 | AF14: 22,2,37 | AG14: 2,33,27,18 | AH14: 35,1,32,10 | AI14: 35,40,28 | AJ14: 35,10,28,1 | AK14: 22,35,18,39 | AL14: 35,22,1,39 | AN14: 35,28,1,40 | AO14: 28,10,35
B15: 12. Shape | C15: 8,10,29,40 | D15: 15,10,26,3 | E15: 29,34,5,4 | F15: 1,40,35 | G15: 14,10,34,40 | H15: 7,2,35 | I15: 35,15,34,18 | J15: 35,10,37,40 | K15: 34,15,10,14 | L15: 33,1,28,13 | M15: 30,14,10,40 | N15: — | O15: 10,40,16 | P15: 10,40,28,34 | Q15: 10,35,4,18 | S15: 35,19,32,39 | T15: 2,32 | U15: 15,37,19 | V15: 15,13,39 | W15: 35,19,32,39 | X15: 7,2,35 | Y15: 35,10,25 | Z15: 10,14,35 | AA15: 14,9,22,35 | AB15: 22,14,19,32 | AC15: 13,35,39,18 | AD15: 28,32,35 | AE15: 28,32,23,16 | AF15: 22,2,37 | AG15: 13,35,1,16 | AH15: 22,10,35,28 | AI15: 22,10,35 | AJ15: 22,10,1 | AK15: 1,22,35,28 | AL15: 17,32,13,38 | AM15: 28,32,13 | AN15: 1,32,17,28 | AO15: 10,35,28,29
B16: 13. Stability of object composition | C16: 21,35,2,39 | D16: 26,39,1,40 | E16: 28,10 | F16: 28,10 | G16: 14,9,13,15 | H16: 1,6,2,36 | I16: 35,1,14,16 | J16: 34,28,35,40 | K16: 33,15,28,18 | L16: 10,35,18,3 | M16: 35,10,18 | N16: 35,40,27,39 | O16: — | P16: 28,6,35,18 | Q16: 32,35,40,4 | S16: 2,35,40 | U16: 22,1,18,4 | X16: 17,9,15 | Y16: 13,27,10,35 | Z16: 2,22,35 | AA16: 10,4,29,15 | AB16: 35,29 | AC16: 3,35,40,10 | AD16: 11,28 | AE16: 2,35,40,10 | AF16: 1,35,28,18 | AG16: 35,40,27,39 | AH16: 1,13,32 | AI16: 35,1,32,13 | AJ16: 1,35,32 | AK16: 35,30,14,24 | AL16: 10,35,13 | AM16: 28,32,35 | AN16: 26,2 | AO16: 35,28
B17: 14. Strength | C17: 1,8,40,15 | D17: 40,26,27,1 | E17: 1,15,8,35 | F17: 15,14,28,26 | G17: 3,34,40,29 | H17: 10,14,29,40 | I17: 10,15,14,7 | J17: 9,14,17,15 | K17: 8,13,26,14 | L17: 10,18,3,14 | M17: 10,3,18,40 | N17: 10,30,35,40 | O17: 35,3,22,39 | P17: — | Q17: 9,18,3,40 | T17: 3,27,16 | U17: 3,27,16 | X17: 29,3,28,35 | Y17: 10,35,14 | Z17: 10,14,35 | AA17: 10,28,24 | AB17: 3,35,13 | AC17: 27,3,26 | AD17: 28,32,13 | AE17: 10,28,29,37 | AF17: 1,35,40,18 | AG17: 28,3,27,35 | AH17: 1,35,13 | AI17: 15,34,33 | AJ17: 32,35,28,34 | AK17: 32,40,28,2 | AL17: 27,11,3 | AM17: 28,32,13 | AN17: 28,35,3 | AO17: 1,28,10
B18: 15. Duration of action - moving | C18: 19,5,34,31 | E18: 2,19,9 | G18: 3,17,19 | I18: 19,10,35,38 | K18: 28,33,18,4 | L18: 3,35,5 | M18: 10,3,18,40 | N18: 19,35,10 | O18: 16,34,31,28 | P18: 10,37,14 | Q18: — | R18: 3,35,13,21 | S18: 19,35,10,38 | T18: 2,19,13 | U18: 28,6,35,18 | W18: 8,35 | X18: 35,11,22,31 | Y18: 3,18,34,31 | Z18: 22,10,1,35 | AA18: 10,30,4 | AB18: 17,9,15 | AC18: 35,10,3 | AD18: 3,27,16 | AE18: 3,27,16,40 | AF18: 35,3,15,19 | AG18: 3,27,35,16 | AH18: 3,27,35,16 | AI18: 21,3,35,13 | AJ18: 35,10,28,3 | AK18: 3,35,10,40 | AL18: 22,2,37 | AM18: 22,3,34 | AN18: 29,3,28,18 | AO18: 35,10,2,18
B19: 16. Duration of action - stationary | D19: 35,10,21 | F19: 35,10,21 | H19: 35,10,21 | J19: 35,10,21 | R19: — | S19: 19,1,35 | U19: 19,2,35,32 | Y19: 1,6,33 | Z19: 19,28,26,35 | AA19: 35,28 | AC19: 1,35,6,10 | AD19: 28,10,2,35 | AE19: 3,35,10 | AF19: 28,10,29,35 | AG19: 28,10,35 | AH19: 28,10,35,23 | AI19: 28,10,29,35 | AJ19: 1,28,10 | AK19: 1,35,13 | AL19: 1,35,29 | AN19: 2,25 | AO19: 12,35,26,18
B20: 17. Temperature | C20: 36,22,6,38 | E20: 22,35,32 | G20: 22,1,18 | I20: 22,35,2,24 | K20: 35,28,21,18 | L20: 35,28,21,18 | M20: 1,28,15,35 | N20: 15,22,33,31 | O20: 15,19,9 | P20: 3,35,38,18 | Q20: 3,35,22,5 | S20: — | T20: 22,15,33,28 | U20: 1,35,32 | V20: 19,32,16 | W20: 2,14,17,25 | X20: 21,17,35,38 | Y20: 21,36,29,31 | Z20: 26,27 | AA20: 2,5,35 | AB20: 28,24,22,26 | AC20: 35,13,8,1 | AD20: 35,32,1 | AE20: 28,32,1,24 | AF20: 22,21,18,27 | AG20: 22,35,31,2 | AH20: 27,2,39,35 | AI20: 28,27,2,31 | AJ20: 35,19 | AK20: 1,6,15 | AL20: 28,17,15,16 | AM20: 26,27,13 | AN20: 2,24,26 | AO20: 35,38
B21: 18. Illumination intensity | E21: 32,13 | F21: 32,26 | G21: 32,30 | I21: 13,16,1,6 | L21: 1 | N21: 2,32 | O21: 32,35,19 | P21: 3,27,16 | Q21: 2,13,19 | S21: 22,15,33,28 | T21: — | U21: 8,35,40,25 | W21: 35,28,34,4 | X21: 10,28,38 | Y21: 28,10,20 | Z21: 35,13 | AA21: 6,13,28,1 | AB21: 32,15,26 | AC21: 32,28,26 | AD21: 32,35,10 | AE21: 28,35,10,23 | AF21: 35,10,3,21 | AG21: 10,3,18,40 | AH21: 22,35,28,10 | AI21: 35,13,22,18 | AJ21: 11,32,13 | AK21: 2,13,28,35 | AL21: 17,32,13,38 | AM21: 32,13,6 | AN21: 32,2 | AO21: 13,16,1,6
B22: 19. Use of energy by moving object | C22: 12,18,28,31 | E22: 19,10,32,18 | G22: 12,28,35 | H22: 12,28,35 | I22: 14,2,39,6 | K22: 12,28 | L22: 19,13,17,24 | M22: 19,14,20,35 | N22: 10,36,14,35 | O22: 10,36,3,14 | P22: 14,35,34,10 | Q22: 35,26,4 | R22: 12,28,35 | S22: 1,35,32 | T22: 8,35,40,25 | U22: — | V22: 19,2,35,32 | W22: 28,26,30 | X22: 19,35,10,38 | Y22: 35,10,38,19 | Z22: 1,35,32,6 | AA22: 12,35,32,26 | AB22: 28,35,6,22 | AC22: 28,35,6,18 | AD22: 6,19,28,24 | AE22: 12,22,35,24 | AF22: 35,24,18,5 | AG22: 35,38,19,18 | AH22: 34,23,16,18 | AI22: 35,37 | AJ22: 35,2,22,26 | AK22: 14,20,19,35 | AL22: 35,32,15,26 | AM22: 6,28,25 | AN22: 3,35,15 | AO22: 28,26,18,35
B23: 20. Use of energy by stationary object | D23: 19,18,36,40 | F23: 1,26 | I23: 7,2,35 | J23: 35,10,19,14 | N23: 15,13,39 | S23: 19,32,16 | U23: 19,2,35,32 | V23: — | W23: 2,35,16 | X23: 19,24,3,14 | Y23: 10,2,22,37 | Z23: 19,22,18 | AA23: 16,20,26,5 | AC23: 28,10,29,35 | AD23: 28,10,35 | AE23: 28,10,35,27 | AF23: 28,18,10,40 | AG23: 35,10,18,5 | AH23: 35,10,18 | AI23: 35,10,18 | AJ23: 4,28,10,34 | AK23: 12,35,26,18 | AL23: 12,28,35 | AM23: 3,6,32 | AN23: 19,35 | AO23: 1,10,26,39
B24: 21. Power | C24: 8,36,38,31 | E24: 19,26,17,27 | G24: 1,10,35,37 | I24: 19,38 | K24: 6,18,38,40 | L24: 2,19,6 | M24: 1,10,35,37 | N24: 19,38 | O24: 17,32,13,38 | P24: 28,10 | Q24: 19,10,2,35 | S24: 1,35,6,27 | T24: 32,35,27,31 | U24: 12,35,28,31 | V24: 2,35,6 | W24: — | X24: 19,10,19,38 | Y24: 7,23,1,21 | Z24: 35,22 | AA24: 10,5,18,32 | AB24: 10,35,40,34 | AC24: 10,35,14 | AD24: 3,35,13,21 | AE24: 10,28,29,37 | AF24: 3,18,35,37 | AG24: 10,13,28,38 | AH24: 5,11,1,23 | AI24: 3,13,6,22 | AJ24: 11,22,22,13 | AK24: 10,21,22 | AL24: 29,1,35,27 | AM24: 3,13,27,10 | AN24: 3,35,10,40 | AO24: 28,29,37,36
B25: 22. Loss of energy | C25: 15,6,19,28 | D25: 19,6,18,9 | E25: 7,2,6,13 | G25: 16,35,38 | I25: 36,38,10,19 | K25: 14,2,39,6 | L25: 26,10,28 | M25: 1,28,35,10 | N25: 2,7,17 | O25: 1,28,35,10 | P25: 3,27,28,35 | Q25: 35,3,22,5 | S25: 35,38 | T25: 28,6,35,18 | U25: 28,27,18,31 | V25: 14,2,39,6 | W25: 19,10,19,38 | X25: — | Y25: 35,6,23,40 | Z25: 10,6,2,34 | AA25: 35,6,22,32 | AB25: 26,35,28,10 | AC25: 28,27,15,3 | AD25: 10,26,35 | AE25: 3,28,35,27 | AF25: 22,35,13,24 | AG25: 22,35,2,24 | AH25: 26,28,10,36 | AI25: 14,2,39,35 | AJ25: 14,2,39,35 | AK25: 2,14,30,40 | AL25: 25,28,2,16 | AM25: 22,21,27,35 | AN25: 2,33,27,18 | AO25: 35,28,10,2
B26: 23. Loss of substance | C26: 35,6,23,40 | D26: 35,6,22,32 | E26: 14,29,10,39 | F26: 10,28,24 | G26: 35,2,10,31 | H26: 10,3,18,40 | I26: 35,10,18,32 | J26: 35,18,10,13 | K26: 14,15,1,16 | L26: 35,10,4 | M26: 33,28,25,10 | N26: 3,35,40,39 | O26: 10,13,28 | P26: 3,35,14 | Q26: 10,35,2,39 | R26: 1,6,33 | S26: 10,1,4 | T26: 28,10 | U26: 35,28,21,18 | V26: 3,18,34,27 | W26: 10,35,4 | X26: 35,16,10,18 | Y26: — | Z26: 15,18,35,10 | AA26: 6,3,10,24 | AB26: 10,29,39,35 | AC26: 10,14,35,3 | AD26: 3,28,35,27 | AE26: 3,28,10,25 | AF26: 35,3,15,23 | AG26: 35,1,32 | AH26: 2,35,6 | AI26: 28,35,15,10 | AJ26: 35,10,28,24 | AK26: 35,18,34 | AL26: 1,28,10,25 | AM26: 3,6,32 | AN26: 28,35,10,23 | AO26: 13,23,15
B27: 24. Loss of information | E27: 10,28,29,35 | G27: 14,9,13 | I27: 26,24 | K27: 22,26,28,32 | L27: 26,32 | M27: 10,16,31,28 | N27: 10,28,35,25 | O27: 2,22 | P27: 10,16,29,35 | Q27: 22,10,1 | R27: 35,24 | S27: 10,6,2,34 | T27: 26,35 | U27: 26,24,32 | V27: 28,26,10 | W27: 10,26,35 | X27: 26,35,10 | Y27: 10,6,2,34 | Z27: — | AA27: 26,24,32 | AB27: 10,28,35 | AC27: 35,18,16,15 | AD27: 10,35,2,39 | AE27: 10,28,23 | AF27: 10,19,2,35 | AG27: 19,10,3,28 | AH27: 28,35,10,23 | AI27: 15,3,32,19 | AJ27: 15,3,29,35 | AK27: 35,18,34 | AL27: 1,28,10 | AM27: 3,6,32 | AN27: 35,23,1,24 | AO27: 10,28,29,35
B28: 25. Loss of time | C28: 10,37,36,5 | D28: 37,36,4 | E28: 4,10,34,17 | F28: 35,3,22,39 | G28: 29,26,4 | H28: 35,38,18,16 | I28: 10,30,4 | J28: 24,34,28,32 | K28: 35,38,18,16 | L28: 10,37,14 | M28: 35,22,2,24 | N28: 2,10,19,30 | O28: 35,20,10,6 | P28: 3,35,39,18 | Q28: 35,22,10,2 | R28: 35,28 | S28: 15,2,29 | T28: 6,13,28,1 | U28: 10,5,18,32 | V28: 35,16,32,18 | W28: 35,6,22,32 | X28: 10,37,14 | Y28: 6,3,10,24 | Z28: 26,24,32 | AA28: — | AB28: 35,29 | AC28: 10,37,36,5 | AD28: 4,28,10,34 | AE28: 4,28,10,34 | AF28: 32,1,10,25 | AG28: 35,28,34,18 | AH28: 10,28,4,34 | AI28: 35,10,2 | AJ28: 4,28,10,34 | AK28: 32,1,28,35 | AL28: 6,29 | AM28: 1,35,29,38 | AN28: 35,38 | AO28: 1,35,4,18
B29: 26. Amount of substance | C29: 35,6,18,31 | E29: 18,3,28,40 | G29: 15,3,29 | H29: 3,13,10,28 | I29: 14,15,18,4 | J29: 3,36,37,10 | K29: 13,3,36,24 | L29: 3,35,31 | M29: 35,10,33,22 | N29: 29,1,35,27 | O29: 35,29,34,28 | P29: 35,14,3 | Q29: 15,2,17,40 | S29: 35,6,13,18 | T29: 19,21,35,28 | U29: 28,35,6,22 | W29: 35,29,34,28 | X29: 35,6,23 | Y29: 10,14,29,35 | Z29: 10,36,14,35 | AA29: 35,29 | AB29: — | AC29: 35,18,10,13 | AD29: 35,22,18,39 | AE29: 10,3,28,24 | AF29: 35,33,29,31 | AG29: 3,35,40,39 | AH29: 29,1,35,27 | AI29: 35,29,25,10 | AJ29: 10,14,35,3 | AK29: 3,35,10,40 | AL29: 29,26,4 | AM29: 29,30,6,13 | AN29: 35,38 | AO29: 14,1,13,16
B30: 27. Reliability | C30: 3,8,10,40 | D30: 3,10,8,28 | E30: 15,9,14,4 | F30: 15,29,28,11 | G30: 17,10,14,16 | H30: 32,35,26,28 | I30: 3,10,14 | J30: 2,35,24 | K30: 21,35,11,28 | L30: 8,28,10,3 | M30: 10,24,35,19 | N30: 10,11,35 | O30: 10,35,29,39 | P30: 3,35,10,40 | Q30: 11,28,10,25 | R30: 3,35,10,40 | S30: 10,3,11 | T30: 19,32,28 | U30: 6,19,28,24 | V30: 6,19,28,24 | W30: 10,35,14 | X30: 21,28,40,3 | Y30: 10,13,28,35 | Z30: 10,35,13,8 | AA30: 10,28,38 | AB30: 10,3,11,35 | AC30: — | AD30: 11,27,16 | AE30: 28,27,15,3 | AF30: 35,3,22,5 | AG30: 11,32,13 | AH30: 27,35,2,40 | AI30: 28,6,35,18 | AJ30: 35,10,28,24 | AK30: 1,35,40,28 | AL30: 13,35,1 | AM30: 27,40,28,8 | AN30: 11,13,27 | AO30: 1,35,29,38
B31: 28. Measurement accuracy | C31: 32,35,26,28 | D31: 28,35,25,26 | E31: 28,26,5,16 | F31: 32,28,3,16 | G31: 26,28,32,3 | H31: 26,28,32,3 | I31: 32,13,6 | J31: 28,13,32,24 | K31: 6,28,32 | L31: 6,28,32 | M31: 28,6,32 | N31: 6,28,32 | O31: 32,35,13 | P31: 28,6,32,26 | Q31: 28,6,32 | R31: 10,26,24 | S31: 32,35,26,28 | T31: 28,32,35,26 | U31: 28,32,13,18 | V31: 32,28,13 | W31: 35,28,2,24 | X31: 28,6,32,26 | Y31: 28,32,2 | Z31: 6,28,32 | AA31: 28,32,13,18 | AB31: 28,32,6,26 | AC31: 28,32,13,26 | AD31: — | AE31: 25,28,35,26 | AF31: 28,35,10,23 | AG31: 28,35,10,23 | AH31: 4,28,10,34 | AI31: 28,6,32,24 | AJ31: 32,35,26,28 | AK31: 28,35,10,16 | AL31: 6,19,28,24 | AM31: 1,6,13,32 | AN31: 28,35,15 | AO31: 32,13,6
B32: 29. Manufacturing precision | C32: 28,32,13,18 | D32: 28,35,27,9 | E32: 10,28,29,37 | F32: 2,32,10 | G32: 28,33,29,32 | H32: 2,29,18,36 | I32: 32,28,3,16 | J32: 28,13,32,24 | K32: 10,28,32,25 | L32: 28,19,34,36 | M32: 3,35,40,10 | N32: 32,30,40 | O32: 30,18 | P32: 3,27 | Q32: 3,27,40 | S32: 35,19,32,24 | T32: 19,35,28,26 | U32: 10,13,19,35 | V32: 35,10,25,28 | W32: 10,28,32 | X32: 11,3,10,32 | Y32: 3,10,25,28 | Z32: 10,28,23 | AA32: 4,28,10,34 | AB32: 10,3,28,24 | AC32: 28,27,15,3 | AD32: 25,28,35,26 | AE32: — | AF32: 35,10,2,16 | AG32: 35,10,25,16 | AH32: 2,35,10,16 | AI32: 35,10,25 | AJ32: 28,35,10 | AK32: 13,35,2 | AL32: 28,6,13 | AM32: 6,28,13,32 | AN32: 32,35,13 | AO32: 35,28,2,24
B33: 30. Object-generated harmful effects | C33: 22,21,27,39 | D33: 2,22,13,24 | E33: 17,1,39,4 | F33: 1,18,35,36 | G33: 22,1,18,4 | H33: 27,2,39,35 | I33: 22,23,37,35 | J33: 34,39,19,27 | K33: 21,22,35,28 | L33: 10,1,34,29 | M33: 10,21,29,40 | N33: 1,22,4 | O33: 33,22,19,40 | P33: 10,1,29,35 | Q33: 11,29,28,27 | R33: 35,27,2,40 | S33: 35,2,40,26 | T33: 35,10,3,21 | U33: 22,10,35 | V33: 22,19,29,40 | W33: 33,3,34 | X33: 22,35,13,24 | Y33: 10,2,22,37 | Z33: 10,19,2,35 | AA33: 32,1,19 | AB33: 1,24,6,27 | AC33: 10,2,22,37 | AD33: 19,22,18 | AE33: 35,10,2,18 | AF33: — | AG33: 24,30,22,40 | AH33: 10,35,13,2 | AI33: 35,11,22,31 | AJ33: 1,35,29,2 | AK33: 10,30,4 | AL33: 14,24,10,37 | AM33: 35,18,27,2 | AN33: 1,22,35,28 | AO33: 10,2,13,19
B34: 31. Harmful side effects | C34: 19,22,15,39 | D34: 35,22,1,39 | E34: 17,15,16,22 | F34: 17,2,18,39 | G34: 22,1,40 | H34: 17,2,40 | I34: 30,18,35,4 | J34: 35,28,3,23 | K34: 35,28,2,24 | L34: 35,28,10,40 | M34: 33,28,18,4 | N34: 22,1,18,4 | O34: 35,40,10,27 | P34: 15,35,22,2 | Q34: 15,22,33,31 | R34: 21,39,16,22 | S34: 22,35,18,39 | T34: 22,35,31,24 | U34: 17,1,40,33 | V34: 22,19,29,28 | W34: 33,3,34 | X34: 22,35,2,24 | Y34: 1,35,32 | Z34: 19,10,3,28 | AA34: 35,28,34,18 | AB34: 3,35,40,39 | AC34: 29,3,28,18 | AD34: 32,3,27,16 | AE34: 3,27,35 | AF34: 24,30,22,40 | AG34: — | AH34: 18,35,37,1 | AI34: 22,15,33,28 | AJ34: 17,1,40,24 | AK34: 22,33,35,2 | AL34: 1,19,32,13 | AM34: 1,3,10,32 | AN34: 1,24,6,27 | AO34: 10,2,22,37
B35: 32. Ease of manufacture | C35: 28,29,15,16 | D35: 1,27,36,13 | E35: 1,10,35,37 | F35: 1,35,16 | G35: 26,17,34,10 | H35: 26,17,34,10 | I35: 24,17,13 | J35: 2,17,26 | K35: 1,32,17,26 | L35: 1,32,17,28 | M35: 4,28,10,34 | N35: 1,32,10,25 | O35: 1,35,13 | P35: 1,35,13 | Q35: 1,32,13,11 | R35: 34,2,28,27 | S35: 15,34,1,16 | T35: 32,24,18,16 | U35: 35,28,34,4 | V35: 32,1,10,25 | W35: 5,11,1,23 | X35: 2,13,15 | Y35: 35,1,11,9 | Z35: 28,10,9,35 | AA35: 10,28,4,34 | AB35: 29,10,27,35 | AC35: 35,10,28,24 | AD35: 4,28,10,34 | AE35: 35,10,28,29 | AF35: 10,35,13,2 | AG35: 10,28,35,23 | AH35: — | AI35: 2,35,10,16 | AJ35: 35,10,28,29 | AK35: 10,35,28,38 | AL35: 10,13,35,7 | AM35: 35,10,13,28 | AN35: 35,28,13,27 | AO35: 1,35,10,28
B36: 33. Ease of operation | C36: 25,2,13,15 | D36: 6,13,1,25 | E36: 1,17,13,12 | F36: 1,17,13,16 | G36: 18,16,15,39 | H36: 1,16,35,15 | I36: 4,18,39,31 | J36: 18,13,34 | K36: 28,13,35 | L36: 2,32,12 | M36: 15,34,29,28 | N36: 32,35,30 | O36: 12,17,28,24 | P36: 15,34,33 | Q36: 32,24,18,16 | R36: 35,28,34,4 | S36: 2,19,13 | T36: 28,32,13 | U36: 4,28,10,34 | V36: 28,2,17,35 | W36: 2,35,13,16 | X36: 15,32,1,13 | Y36: 18,1 | Z36: 16,10,28,35 | AA36: 4,18,39,34 | AB36: 2,35,30,16 | AC36: 35,10,14 | AD36: 35,1,16,11 | AE36: 10,36,3,37 | AF36: 35,3,22,39 | AG36: 35,28,2 | AH36: 28,29,15,16 | AI36: — | AJ36: 25,2,35,11 | AK36: 1,35,16 | AL36: 15,37,18 | AM36: 1,28,13,27 | AN36: 15,1,28,16 | AO36: 18,10,13,34
B37: 34. Ease of repair | C37: 2,27,35,40 | D37: 2,27,35,40 | E37: 1,28,10,25 | F37: 3,18,27,40 | G37: 15,13,32 | H37: 16,25 | I37: 25,2,35,11 | J37: 1,28,35,10 | K37: 34,9 | L37: 1,11,10 | M37: 13,35,1,11 | N37: 2,13,15,16 | O37: 27,11,3 | P37: 1,32,10,25 | Q37: 13,35,2 | R37: 25,10,28,1 | S37: 11,10,1,16 | T37: 11,13,1 | U37: 1,13,2,4 | V37: 2,35,13,10 | W37: 35,11,22,31 | X37: 34,9,27,40 | Y37: 15,10,32,2 | Z37: 15,1,32,19 | AA37: 35,28,34,18 | AB37: 35,10,28,29 | AC37: 2,35,3,25 | AD37: 32,28,2,24 | AE37: 2,35,28,26 | AF37: 35,28,10,6 | AG37: 2,10,3 | AH37: 35,10,28,29 | AI37: 25,2,35,11 | AJ37: — | AK37: 1,32,2,9 | AL37: 35,28,6 | AM37: 3,1,32,13 | AN37: 35,28,25,10 | AO37: 2,10,28,25
B38: 35. Adaptability or versatility | C38: 15,35,29 | D38: 15,29,37,28 | E38: 1,35,16 | F38: 35,30,29,7 | G38: 15,16,35,28 | H38: 35,10,14 | I38: 15,37,1,8 | J38: 35,30,14 | K38: 35,28,33,18 | L38: 15,10,2 | M38: 35,10,14 | N38: 14,1,16,10 | O38: 2,35,15 | P38: 15,37,1,8 | Q38: 35,30,14,2 | R38: 35,10,14 | S38: 3,15,40,14 | T38: 35,28 | U38: 35,14,3 | V38: 35,14,1,16 | W38: 15,37,1 | X38: 35,14,2 | Y38: 14,15,1,16 | Z38: 35,14,18,34 | AA38: 35,30,14,18 | AB38: 35,10,21,16 | AC38: 35,28,21,18 | AD38: 35,13,8,24 | AE38: 35,5,1,10 | AF38: 35,11,32,31 | AG38: 35,10,28 | AH38: 35,10,37 | AI38: 1,35,16 | AJ38: 32,1,2,9 | AK38: — | AL38: 1,6,13,26 | AM38: 15,29,28,11 | AN38: 1,15,29,16 | AO38: 1,35,13
B39: 36. Device complexity | C39: 26,30,34,36 | D39: 2,26,35,39 | E39: 1,19,26,24 | F39: 26,30,34,36 | G39: 2,35 | H39: 2,10,34,31 | I39: 19,30,35,2 | J39: 2,19,6 | K39: 35,39,38 | L39: 28,27,18,31 | M39: 15,10,37,28 | N39: 15,10,2 | O39: 15,10,37 | P39: 2,14,17,25 | Q39: 1,35,13 | R39: 35,10,28 | S39: 35,19,32,24 | T39: 32,35,27,31 | U39: 26,2,19,16 | V39: 2,19,13 | W39: 19,13,17,24 | X39: 13,29,2,4 | Y39: 35,22,18,39 | Z39: 35,10,18 | AA39: 1,19,26,17 | AB39: 1,19,26 | AC39: 10,26,13 | AD39: 19,26,24,32 | AE39: 10,26,32,28 | AF39: 1,6,29 | AG39: 35,26,2,4 | AH39: 10,16,3,28 | AI39: 28,1,9,26 | AJ39: 1,15,29,16 | AK39: 15,10,37,28 | AL39: — | AM39: 2,14,30,40 | AN39: 28,10,19,34 | AO39: 15,17,20
B40: 37. Difficulty of detecting and measuring | C40: 28,26,18,35 | D40: 28,26,35,10 | E40: 28,26,18,35 | F40: 2,26,35,10 | G40: 2,28,10,25 | H40: 10,18,32,39 | I40: 2,6,34,14 | J40: 28,6,13,26 | K40: 35,36,37,32 | L40: 28,15,10,36 | M40: 6,35,36,37 | N40: 35,1,13,11 | O40: 2,26,10,34 | P40: 28,26,10,34 | Q40: 28,15,10,36 | S40: 35,26,24,37 | T40: 28,26,10,34 | U40: 28,26,18,35 | V40: 35,26,28,10 | W40: 2,6,28,26 | X40: 35,36,37,32 | Y40: 6,28,35,26 | Z40: 3,6,5,26 | AA40: 35,26,24,37 | AB40: 35,28,34,26 | AC40: 28,26,10,34 | AD40: 1,13,32,19 | AE40: 1,13,32,19 | AF40: 35,18,10,13 | AG40: 35,10,18,5 | AH40: 35,10,13,28 | AI40: 35,10,18,16 | AJ40: 35,18,10,13 | AK40: 10,13,28,29 | AL40: 10,4,28,34 | AM40: — | AN40: 3,27,35,16 | AO40: 6,13,28,1
...

Sheet Separation Principles
B1: Physical Contradiction — Separation Principles & Inventive Principles
B3: Separate in TIME
B4: One solution at one time; the opposite at another time.
B5: # | C5: Principle | D5: How it resolves the physical contradiction
B6: 1 | C6: Segmentation | D6: Divide object into independent parts that can behave differently at different times.
B7: 7 | C7: Nested doll | D7: Place objects inside one another; unfold/collapse as needed over time.
B8: 9 | C8: Prior counteraction | D8: Pre-stress components to compensate for future undesired changes.
B9: 10 | C9: Prior action | D9: Perform required action in advance, or pre-arrange objects for convenient action.
B10: 11 | C10: Cushion in advance | D10: Compensate for low reliability by preparing emergency means in advance.
B11: 15 | C11: Dynamics | D11: Make object/environment automatically adapt at each stage of operation.
B12: 18 | C12: Mechanical vibration | D12: Set object into oscillation; use piezoelectric, ultrasonic or resonance effects.
B13: 19 | C13: Periodic action | D13: Replace continuous action with periodic (impulse) action; use pulses to optimize.
B14: 21 | C14: Rushing through | D14: Conduct harmful/hazardous operations at very high speed to reduce exposure.
B15: 34 | C15: Discarding & recovering | D15: After completing function, discard or restore elements directly during operation.
B17: Separate in SPACE
B18: One solution in one place; the opposite solution in another place.
B19: # | C19: Principle | D19: How it resolves the physical contradiction
B20: 1 | C20: Segmentation | D20: Divide object into independent parts located in different spatial zones.
B21: 2 | C21: Taking out | D21: Separate interfering part or property from object; extract only what is needed.
B22: 3 | C22: Local quality | D22: Change object/environment from homogeneous to heterogeneous; vary properties by zone.
B23: 4 | C23: Asymmetry | D23: Introduce asymmetry if object is symmetrical; use existing asymmetry to advantage.
B24: 7 | C24: Nested doll | D24: Place objects inside one another; contain multiple objects in the same location.
B25: 13 | C25: The other way round | D25: Invert the action; make moving parts fixed and fixed parts movable.
B26: 14 | C26: Spheroidality/Curvature | D26: Replace linear parts with curved; use spirals, helices, or spheres.
B27: 17 | C27: Another dimension | D27: Move object into two- or three-dimensional space; use multi-layered arrangement.
B28: 24 | C28: Intermediary | D28: Use an intermediate object to carry, transmit or buffer between two zones.
B29: 30 | C29: Flexible membranes & films | D29: Use flexible shells and thin films instead of rigid structures to separate zones.
B31: Separate on CONDITION
B32: Opposite solutions in the same place and time — one for each condition.
B33: # | C33: Principle | D33: How it resolves the physical contradiction
B34: 28 | C34: Replace mechanical system | D34: Replace mechanical system with optical, acoustic, thermal or olfactory system.
B35: 29 | C35: Pneumatics & hydraulics | D35: Use gas or liquid parts instead of solid; inflatable, hydrostatic structures.
B36: 31 | C36: Porous materials | D36: Make object porous; use porous insert; if porous, fill pores with useful substance.
B37: 32 | C37: Colour changes | D37: Change colour of object or environment; change transparency; use luminescent traces.
B38: 35 | C38: Parameter change | D38: Change physical state, concentration, flexibility, temperature, or other parameters.
B39: 36 | C39: Phase transition | D39: Implement effects occurring during phase transitions (volume changes, heat absorption).
B40: 38 | C40: Accelerated oxidation | D40: Replace ordinary air with enriched or pure oxygen; use ozone or ozonized oxygen.
B41: 39 | C41: Inert atmosphere | D41: Replace normal environment with inert one; carry out processes in vacuum.
B43: Separate by SYSTEM
B44: Separate by scale — sub-system, super-system, or switch to another system.
...

Sheet TC Matrix
B1: Technical Contradiction — Common Parameter Pairs & Recommended Principles
B2: Parameter to IMPROVE | C2: Parameter that WORSENS | D2: Recommended TRIZ Principles
B3: Strength / Force | C3: Weight / Mass | D3: 1, 8, 15, 40 — Segmentation, Anti-weight, Dynamics, Composites
B4: Speed | C4: Energy use | D4: 10, 13, 28, 38 — Prior action, Other way round, Replace mech., Oxidation
B5: Reliability | C5: Complexity | D5: 1, 11, 27, 35 — Segmentation, Cushion in advance, Cheap objects, Param. change
B6: Productivity / Throughput | C6: Device complexity | D6: 5, 10, 15, 34 — Merging, Prior action, Dynamics, Discarding & recovering
B7: Accuracy / Precision | C7: Time / Speed of operation | D7: 10, 28, 32, 35 — Prior action, Replace mech., Colour changes, Param. change
B8: Thermal conductivity | C8: Weight / Mass | D8: 3, 15, 30, 40 — Local quality, Dynamics, Flexible membranes, Composites
B9: Adaptability | C9: Device stability | D9: 1, 15, 29, 35 — Segmentation, Dynamics, Pneumatics, Param. change
B10: Manufacturability | C10: Accuracy | D10: 10, 28, 32, 35 — Prior action, Replace mech., Colour changes, Param. change
B11: Power / Energy | C11: Temperature | D11: 12, 18, 28, 35 — Equipotentiality, Vibration, Replace mech., Param. change
B12: Volume / Capacity | C12: Weight | D12: 1, 7, 17, 40 — Segmentation, Nested doll, Another dimension, Composites
B13: Strength | C13: Stress on object | D13: 1, 8, 15, 35 — Segmentation, Anti-weight, Dynamics, Param. change
... B17: Information density | C17: Device complexity | D17: 1, 5, 26, 33 — Segmentation, Merging, Copying, Homogeneity
B19: Note: For the full 39×39 Altshuller contradiction matrix, use the principle numbers above to look up full definitions in the Appendix sheet.

Sheet Principle Scoring
B1: Principle Scoring & Prioritisation — Rate Your Shortlisted Principles
B2: Score each criterion 1–5 (1=Very low, 5=Very high). Priority Score auto-calculates as weighted total out of 20. Top principle shown at bottom.
B3: # | C3: Principle name (auto) | D3: Feasibility (1–5) | E3: Impact on problem (1–5) | F3: Speed to implement (1–5) | G3: Cost (inverse, 1–5) | H3: Priority score /20 | I3: Notes / rationale
C4: =IFERROR(VLOOKUP(B4,Appendix!$A:$B,2,0),"") | H4: =IFERROR(IF(OR(D4="",E4="",F4="",G4=""),"",ROUND((D4*0.3+E4*0.35+F4*0.2+G4*0.15)*4,1)),"")
C5: =IFERROR(VLOOKUP(B5,Appendix!$A:$B,2,0),"") | H5: =IFERROR(IF(OR(D5="",E5="",F5="",G5=""),"",ROUND((D5*0.3+E5*0.35+F5*0.2+G5*0.15)*4,1)),"")
C6: =IFERROR(VLOOKUP(B6,Appendix!$A:$B,2,0),"") | H6: =IFERROR(IF(OR(D6="",E6="",F6="",G6=""),"",ROUND((D6*0.3+E6*0.35+F6*0.2+G6*0.15)*4,1)),"")
C7: =IFERROR(VLOOKUP(B7,Appendix!$A:$B,2,0),"") | H7: =IFERROR(IF(OR(D7="",E7="",F7="",G7=""),"",ROUND((D7*0.3+E7*0.35+F7*0.2+G7*0.15)*4,1)),"")
C8: =IFERROR(VLOOKUP(B8,Appendix!$A:$B,2,0),"") | H8: =IFERROR(IF(OR(D8="",E8="",F8="",G8=""),"",ROUND((D8*0.3+E8*0.35+F8*0.2+G8*0.15)*4,1)),"")
C9: =IFERROR(VLOOKUP(B9,Appendix!$A:$B,2,0),"") | H9: =IFERROR(IF(OR(D9="",E9="",F9="",G9=""),"",ROUND((D9*0.3+E9*0.35+F9*0.2+G9*0.15)*4,1)),"")
C10: =IFERROR(VLOOKUP(B10,Appendix!$A:$B,2,0),"") | H10: =IFERROR(IF(OR(D10="",E10="",F10="",G10=""),"",ROUND((D10*0.3+E10*0.35+F10*0.2+G10*0.15)*4,1)),"")
C11: =IFERROR(VLOOKUP(B11,Appendix!$A:$B,2,0),"") | H11: =IFERROR(IF(OR(D11="",E11="",F11="",G11=""),"",ROUND((D11*0.3+E11*0.35+F11*0.2+G11*0.15)*4,1)),"")
C12: =IFERROR(VLOOKUP(B12,Appendix!$A:$B,2,0),"") | H12: =IFERROR(IF(OR(D12="",E12="",F12="",G12=""),"",ROUND((D12*0.3+E12*0.35+F12*0.2+G12*0.15)*4,1)),"")
C13: =IFERROR(VLOOKUP(B13,Appendix!$A:$B,2,0),"") | H13: =IFERROR(IF(OR(D13="",E13="",F13="",G13=""),"",ROUND((D13*0.3+E13*0.35+F13*0.2+G13*0.15)*4,1)),"")
C14: =IFERROR(VLOOKUP(B14,Appendix!$A:$B,2,0),"") | H14: =IFERROR(IF(OR(D14="",E14="",F14="",G14=""),"",ROUND((D14*0.3+E14*0.35+F14*0.2+G14*0.15)*4,1)),"")
C15: =IFERROR(VLOOKUP(B15,Appendix!$A:$B,2,0),"") | H15: =IFERROR(IF(OR(D15="",E15="",F15="",G15=""),"",ROUND((D15*0.3+E15*0.35+F15*0.2+G15*0.15)*4,1)),"")
B18: Weights: Feasibility 30% · Impact 35% · Speed 20% · Cost 15% | Score = weighted total × 4 (max 20.0)
B21: Top priority | C21: =IFERROR(INDEX(C4:C15,MATCH(MAX(H4:H15),H4:H15,0)),"— enter scores above —") | G21: =IFERROR(TEXT(MAX(H4:H15),"0.0")&" / 20","—")

Sheet Case Study Library
B1: TRIZ Case Study Library — Real-World Solved Examples
B2: Industry | C2: Problem | D2: Contradiction | E2: Principles | F2: Solution applied | G2: Outcome
B3: Semiconductor | C3: CTE mismatch causing delamination in 3D stacked die packages | D3: Technical: thermal conductivity vs CTE compatibility | E3: 3,15,35,40 | F3: Graded CTE interlayer with nano-silver composites; viscoelastic MUF with Tg tuned to 85–100°C operating window | G3: Peak stress reduced ~30%; delamination eliminated in 1000-cycle thermal test
B4: Aerospace | C4: Wing must be strong for turbulence loads but light for fuel efficiency | D4: Technical: strength vs weight | E4: 1,8,15,40 | F4: CFRP with variable fibre orientation by load zone (local quality); hollow lattice spar (segmentation + nested doll) | G4: 40–50% weight reduction vs aluminium; now standard in commercial aviation
B5: Automotive | C5: Engine: high power but low NOx emissions | D5: Physical: combustion temp must be high (efficiency) AND low (NOx reduction) | E5: 10,35,36 | F5: Cylinder deactivation at low load; exhaust gas recirculation; catalytic converter for residual emissions | G5: Euro 6 compliance achieved without significant power loss
B6: Medical devices | C6: Stent must be rigid enough to hold artery but flexible to navigate vessels | D6: Physical: stiffness must be high AND low simultaneously | E6: 15,35,36,40 | F6: Nitinol shape-memory alloy — flexible at insertion temperature, rigid at body temperature; composite flexible-rigid segments | G6: Navigates vessels <3mm; deployed reliably; now standard in coronary stenting
B7: Consumer electronics | C7: Smartphone battery: longer life but remain thin and light | D7: Technical: energy capacity vs device volume | E7: 5,7,17,35 | F7: 3D battery cell stacking; silicon anode material for higher energy density; cells merged into structural chassis | G7: Energy density improved 2× over 5 years; thickness maintained below 8mm
B8: Manufacturing | C8: Welding speed must be high but low heat input needed to avoid distortion | D8: Technical: productivity vs harmful side effects | E8: 10,18,28,35 | F8: Laser welding replacing arc (replace mechanical system); pulsed mode reduces heat (periodic action); friction stir for aluminium | G8: Distortion reduced >80%; speed increased 3×; widely used in EV battery manufacturing
B9: Construction | C9: Concrete must resist tensile cracking but is weak in tension | D9: Physical: resist tension AND compression simultaneously | E9: 9,10,40 | F9: Pre-stressed post-tensioned concrete: steel tendons pre-loaded (prior counteraction); composite rebar reinforcement | G9: Enables long-span bridges; 20–30% material reduction vs conventional reinforced concrete
B10: Packaging | C10: Food packaging must seal firmly but open easily by consumers | D10: Physical: seal must be strong AND weak simultaneously | E10: 1,15,28,35 | F10: Easy-peel film with weak-bond layer at opening zone (local quality); hermetic seal retained on remaining perimeter; tear-notch (prior action) | G10: Peel force <5N achieved while maintaining hermetic seal; widely adopted in food industry
B11: Oil and gas | C11: Drill bit must penetrate hard rock efficiently but not wear quickly | D11: Technical: cutting efficiency vs durability | E11: 3,27,35,40 | F11: PDC bits with composite diamond cutting elements; diamond layer on face only (local quality); replaceable cutter inserts | G11: Bit life extended 5–10×; penetration rate increased; dominant technology in oil and gas
B12: Software | C12: System must process data fast but store complete audit history | D12: Technical: speed vs loss of information | E12: 1,5,15,26 | F12: Event sourcing: separate current state (fast) from full event log; CQRS pattern; asynchronous log processing (dynamics) | G12: Query response <10ms; full audit trail; adopted in banking and healthcare
B13: Textiles | C13: Protective workwear must resist flame but remain comfortable | D13: Physical: must insulate AND be breathable simultaneously | E13: 3,30,35,40 | F13: Outer layer: flame-resistant Nomex; inner layer: moisture-wicking mesh (local quality + flexible membranes); composite construction | G13: Arc flash protection 40 cal/cm²; moisture transmission 800g/m²/day; standard in electrical utilities
B14: Agriculture | C14: Pesticide must cover all plant surfaces but not contaminate groundwater | D14: Technical: substance coverage vs harmful side effects | E14: 1,3,10,35 | F14: Precision drone spraying on affected zones only (local quality); electrostatic nozzles (parameter change); timed at optimal absorption (prior action) | G14: Pesticide usage reduced 70–80%; run-off contamination reduced; yield maintained

Sheet Problem History Log
B1: Problem History Log — Personal TRIZ Knowledge Base
B2: Log each TRIZ session here. To start a new problem: right-click the TRIZ Navigator tab → Move or Copy → tick Create a copy. Then record the outcome below. Statistics at the bottom auto-update.
B3: Date | C3: System / product | D3: Problem summary | E3: Contradiction type | F3: Separation / matrix path | G3: Principles used | H3: Innovation level | I3: Solution chosen | J3: Status
B4: 2024 | C4: HBM stack — 3D IC package | D4: CTE mismatch and thermal dissipation in stacked dies | E4: Physical Contradiction | F4: Separate on Condition / Separate in Time | G4: 15, 35, 5, 3 | H4: Level 2 | I4: A2: Viscoelastic MUF with Tg 85–100°C; A1: Graded CTE interlayer | J4: In progress
B26: Session statistics (auto-calculated)
B27: Total sessions logged | F27: =COUNTA(C4:C23)
B28: Technical contradictions | F28: =COUNTIF(E4:E23,"Technical Contradiction")
B29: Physical contradictions | F29: =COUNTIF(E4:E23,"Physical Contradiction")
B30: Level 3–5 solutions | F30: =COUNTIF(H4:H23,"Level 3")+COUNTIF(H4:H23,"Level 4")+COUNTIF(H4:H23,"Level 5")
B31: Implemented solutions | F31: =COUNTIF(J4:J23,"Implemented")
B32: In progress | F32: =COUNTIF(J4:J23,"In progress")

Sheet Appendix
A1: TRIZ — 40 Inventive Principles: Definitions & Examples
A2: # | B2: Principle name | C2: Definition | D2: Engineering / tech example | E2: Cross-industry / everyday example
A3: 1 | B3: Segmentation | C3: Divide an object into independent parts; make it sectional; increase the degree of fragmentation. | D3: Modular aircraft fuselage sections allow independent manufacture and assembly; segmented turbine blades. | E3: Modular furniture (IKEA flat-pack); segmented chocolate bar; sectional sofa.
A4: 2 | B4: Taking out | C4: Separate an interfering part or property from an object, or extract only the necessary part or property. | D4: Extract only the necessary signal from noise in sensor design; remove heat source from sensitive electronics. | E4: Juicer separates juice from pulp; noise-cancelling headphones extract signal from ambient noise.
A5: 3 | B5: Local quality | C5: Transition from homogeneous to heterogeneous structure; make each part function in optimal conditions; make each part fulfil a different and useful function. | D5: Graded CTE interlayer in semiconductor packaging; variable-density foam in automotive seating. | E5: Pencil with eraser at one end; Swiss Army knife; bifocal lens with different zones.
A6: 4 | B6: Asymmetry | C6: Change the shape from symmetrical to asymmetrical; if already asymmetrical, increase the degree of asymmetry. | D6: Asymmetric turbine blade profiles for improved aerodynamics; non-symmetric connector shapes to prevent mis-insertion. | E6: Ergonomic mouse designed for the right hand; asymmetric tyre tread for wet vs dry grip.
A7: 5 | B7: Merging | C7: Bring closer in space or time objects or operations; assemble identical or similar parts; increase degree of unity. | D7: System-on-chip (SoC) merging CPU, GPU, memory controller; co-packaging of logic and HBM on the same interposer. | E7: Smartphone merging phone, camera, GPS, music player; combined shampoo-conditioner.
A8: 6 | B8: Universality | C8: Make a part or object perform multiple functions, eliminating the need for other parts. | D8: Universal testing machine performing tensile, compression, and shear tests; multimeter measuring voltage, current, resistance. | E8: Sofa bed; Swiss Army knife; mobile phone replacing camera, compass, calculator.
A9: 7 | B9: Nested doll | C9: Place one object inside another; pass one object through a cavity in another; increase the number of nesting levels. | D9: Telescoping antenna; retractable landing gear; nested heat exchangers. | E9: Russian matryoshka dolls; retractable ballpoint pen; collapsible measuring cup.
A10: 8 | B10: Anti-weight | C10: Compensate for the weight of an object by merging it with another object that provides a lifting force. | D10: Counterweighted robotic arm reducing motor torque requirements; buoyancy-compensated underwater vehicle. | E10: Counterweight on a crane; helium balloon offsetting payload weight.
A11: 9 | B11: Prior counteraction | C11: Pre-stress a component to compensate for undesirable working stress; if known in advance that an object will experience harmful tension, apply anti-tension beforehand. | D11: Pre-stressed concrete beams; pre-tensioned springs in mechanisms; pre-compressed seals. | E11: Compression stockings preventing swelling on long flights; pre-soaking wood before bending.
A12: 10 | B12: Prior action | C12: Perform required changes to an object completely or partially in advance; pre-arrange objects so they can come into action without wasting time and from the most convenient position. | D12: Pre-applied adhesive on PCB pads; pre-loaded spring mechanisms; prefabricated construction modules. | E12: Pre-cut vegetables sold in supermarkets; coffee machine with timer; mise en place in cooking.
A13: 11 | B13: Cushion in advance | C13: Compensate for the relatively low reliability of an object by preparing emergency means in advance. | D13: Redundant data storage (RAID); backup power supply (UPS); safety factor in structural design. | E13: Car spare tyre; airplane supplemental oxygen masks; emergency exit routes.
A14: 12 | B14: Equipotentiality | C14: Change the operating conditions so that an object need not be raised or lowered. | D14: Pit stop design allowing cars to drive over mechanics without lifting; flush-mounted connectors. | E14: Canal locks equalising water levels; loading dock at truck-bed height eliminating forklifts.
... A42: 40 | B42: Composite materials | C42: Transition from homogeneous to composite (multiple) materials. | D42: Carbon-fibre reinforced polymer (CFRP) structures; metal-matrix composites; EMC mold with embedded Cu HRL. | E42: Reinforced concrete (steel + concrete); plywood; Gore-Tex fabric; fibre-optic cable.

Sheet LookupData
A1: 1. Weight of moving object | C1: 1. Weight of moving object||1. Weight of moving object | D1: —
A2: 2. Weight of stationary object | C2: 1. Weight of moving object||2. Weight of stationary object | D2: 15,8,29,34
A3: 3. Length of moving object | C3: 1. Weight of moving object||3. Length of moving object | D3: 29,17,38,34
A4: 4. Length of stationary object | C4: 1. Weight of moving object||5. Area of moving object | D4: 29,2,40,28
A5: 5. Area of moving object | C5: 1. Weight of moving object||7. Volume of moving object | D5: 2,8,15,38
A6: 6. Area of stationary object | C6: 1. Weight of moving object||9. Speed | D6: 2,28,13,38
A7: 7. Volume of moving object | C7: 1. Weight of moving object||10. Force | D7: 8,1,37,18
A8: 8. Volume of stationary object | C8: 1. Weight of moving object||11. Stress or pressure | D8: 17,10,4
A9: 9. Speed | C9: 1. Weight of moving object||12. Shape | D9: 1,8,15,34
A10: 10. Force | C10: 1. Weight of moving object||13. Stability of object composition | D10: 28,10
A11: 11. Stress or pressure | C11: 1. Weight of moving object||14. Strength | D11: 1,8,40,15
A12: 12. Shape | C12: 1. Weight of moving object||15. Duration of action - moving | D12: 15,14,28,26
... A39: 39. Productivity | C39: 2. Weight of stationary object||11. Stress or pressure | D39: 13,19,10,37
C40: 2. Weight of stationary object||12. Shape | D40: 17,9,15
C41: 2. Weight of stationary object||13. Stability of object composition | D41: 28,10
C42: 2. Weight of stationary object||14. Strength | D42: 10,28,8
C43: 2. Weight of stationary object||16. Duration of action - stationary | D43: 35,10,21
C44: 2. Weight of stationary object||20. Use of energy by stationary object | D44: 19,18,36,40
C45: 2. Weight of stationary object||22. Loss of energy | D45: 18,19,28,1
C46: 2. Weight of stationary object||23. Loss of substance | D46: 15,18,35,34
C47: 2. Weight of stationary object||25. Loss of time | D47: 10,20,26,5
C48: 2. Weight of stationary object||27. Reliability | D48: 10,35,29,39
C49: 2. Weight of stationary object||28. Measurement accuracy | D49: 28,32,10
C50: 2. Weight of stationary object||29. Manufacturing precision | D50: 28,32,10
C51: 2. Weight of stationary object||30. Object-generated harmful effects | D51: 35,11,22,31
... C1354: 39. Productivity||39. Productivity | D1354: —

Sheet DetailedPrinciples
A1: 1 | B1: Segmentation | C1: [A] [A] Divide an object into independent parts • Different focal length lenses for a camera • Gator-grip socket spanner • Multi-pin connectors • Multiple pistons in an internal combustion engine • Multi-engined aircraft • Stratification of different constituents inside a chemical process vessel [B] Make an object sectional - easy to assemble or disassemble • Rapid-release fasteners for bicycle saddle/wheel/etc • Quick disconnect joints in plumbing and hydraulic systems • Single fastener V-band clamps on flange joints • Loose-leaf paper in a ring binder [C] Increase the degree of fragmentation or segmentation • Multiple control surfaces on aerodynamic structures • 16 and 24 valve versus 8 valve internal combustion engines • Multi-zone combustion system • Build up a component from layers (e.g. stereo-lithography, welds, etc)
A2: 2 | B2: Taking out | C2: [A] [A] Extract the disturbing part or property from an object • Non-smoking areas in restaurants or in railway carriages • Children-only areas in public places and home • Sunday school • Public bars and lounge bars in pubs • Women or men only bars / waiting rooms • Air Conditioning in the room where you want it with the noise of the system outside the room [B] Extract the only necessary part (or property) of an object • Scarecrow • Sound of a barking dog (with no dog) as a burglar alarm • Economy class on planes (travel but no frills)
A3: 3 | B3: Local quality | C3: [A] [A] Change of an object's structure from uniform to non-uniform • Reduce drag on aerodynamic surfaces by adding riblets or 'shark-skin' protrusions • Moulded hand grips on tools • Drink cans shaped to facilitate stable stacking • Material surface treatments / coatings - plating, • Erosion / corrosion protection, case hardening, non-stick, etc [B] Change an action or an external environment (or external influence) from uniform to non-uniform • Introduce turbulent flow around an object to alter heat transfer properties • Strobe lighting • Take account of extremes of weather conditions when designing outdoor systems • Use a gradient instead of constant temperature, density, or pressure [C] Make each part of an object function in conditions most suitable for its operation • Freezer compartment in refrigerator • Different zones in the combustion system of an engine • Night-time adjustment on a rear-view mirror • Lunch box with special compartments for hot and cold solid foods and for liquids [D] Make each part of an object fulfil a different and/or complementary useful function • Swiss-Army knife • Combined can and bottle opener • Sharp and blunt end of a drawing pin • Rubber on the end of a pencil • Hammer with nail puller
A4: 4 | B4: Asymmetry | C4: [A] [A] Change the shape or properties of an object from symmetrical to asymmetrical • Asymmetrical funnel allows higher flow-rate than normal funnel • Put a flat spot on a cylindrical shaft to attach a locking feature • Oval and complex shaped O-rings • Coated glass or paper • Electric Plug • Introduction of angled or scarfed geometry features on component edges • Cutaway on a guitar improves access to high notes • Spout of a jug • Cam • Ratchet • Aerofoil – asymmetry generates lift • Eccentric drive • Keys [B] Change the shape of an object to suit external asymmetries (e.g. ergonomic features) • Human-shaped seating, etc • Design for left and right handed users • Finger and thumb grip features on objects • Spectacles • Car steering system compensates for camber in road • Wing design compensated for asymmetric flow produced by propeller • Turbomachinery design for boundary layer flows (‘end-bend’) [C] If an object is asymmetrical, increase its degree of asymmetry • Use of variable control surfaces to alter lift properties of an aircraft wing • Special connectors with complex shape/pin configurations to ensure correct assembly • Introduction of several different measurement scales on a ruler
A5: 5 | B5: Merging | C5: [A] [A] Bring closer together (or merge) identical or similar objects or operations in space • Automatic rifle / machine gun • Multi-colour ink cartridges • Multi-blade razors • Bi-focal lens spectacles • Double / triple glazing • Strips of staples • Catamaran / trimaran [B] Make objects or operations contiguous or parallel; bring them together in time • Combine harvester • Manufacture cells • Grass collector on a lawn-mower • Mixer taps • Pipe-lined computer processors perform different stages in a calculation simultaneously • Vector processors perform the same process on several sets of data in a single pass • Fourier analysis – integration of many sine curves
A6: 6 | B6: Universality | C6: [A] [A] Make an object perform multiple functions; eliminate the need for other parts • Child's car safety seat converts to a pushchair • Home entertainment centre • Swiss Army knife • Grill in a microwave oven • CD used as a storage medium for multiple data types • Cleaning strip at beginning of a cassette tape cleans tape heads • Cordless drill also acts as screwdriver, sander, polisher, etc
A7: 7 | B7: Nested Doll | C7: [A] [A] Place one object inside another • Retractable aircraft under-carriage • Voids in 3D structures • Injected cavity-wall insulation • Paint-brush attached to inside of lid of nail-varnish, etc • Lining inside a coat [B] Place multiple objects inside others • Nested tables • Telescope • Measuring cups or spoons • Stacking chairs • Multi-layer erosion/corrosion coatings [C] Make one part pass (dynamically) through a cavity in the other • Telescopic car aerial • Retractable power-lead in vacuum cleaner • Seat belt retraction mechanism • Tape measure
